{
 "cells": [
  {
   "cell_type": "markdown",
   "metadata": {},
   "source": [
    "# A Simple TF 2.2 notebook\n",
    "\n",
    "This is intended as a simple, short introduction to the operations competitors will need to perform with TPUs."
   ]
  },
  {
   "cell_type": "code",
   "execution_count": 9,
   "metadata": {
    "_cell_guid": "b1076dfc-b9ad-4769-8c92-a6c4dae69d19",
    "_uuid": "8f2839f25d086af736a60e9eeb907d3b93b6e0e5",
    "execution": {
     "iopub.execute_input": "2022-11-10T14:04:11.410985Z",
     "iopub.status.busy": "2022-11-10T14:04:11.410567Z",
     "iopub.status.idle": "2022-11-10T14:04:18.636471Z",
     "shell.execute_reply": "2022-11-10T14:04:18.635430Z",
     "shell.execute_reply.started": "2022-11-10T14:04:11.410885Z"
    }
   },
   "outputs": [
    {
     "name": "stdout",
     "output_type": "stream",
     "text": [
      "Tensorflow version 2.10.0\n"
     ]
    }
   ],
   "source": [
    "import tensorflow as tf\n",
    "import tensorflow_addons as tfa\n",
    "#from kaggle_datasets import KaggleDatasets\n",
    "import numpy as np\n",
    "import os\n",
    "\n",
    "print(\"Tensorflow version \" + tf.__version__)"
   ]
  },
  {
   "cell_type": "markdown",
   "metadata": {},
   "source": [
    "# Detect my accelerator"
   ]
  },
  {
   "cell_type": "code",
   "execution_count": 7,
   "metadata": {
    "execution": {
     "iopub.execute_input": "2022-11-10T14:07:51.707999Z",
     "iopub.status.busy": "2022-11-10T14:07:51.707363Z",
     "iopub.status.idle": "2022-11-10T14:07:58.204558Z",
     "shell.execute_reply": "2022-11-10T14:07:58.203552Z",
     "shell.execute_reply.started": "2022-11-10T14:07:51.707954Z"
    }
   },
   "outputs": [
    {
     "name": "stdout",
     "output_type": "stream",
     "text": [
      "REPLICAS:  1\n"
     ]
    }
   ],
   "source": [
    "# Detect hardware, return appropriate distribution strategy\n",
    "try:\n",
    "    tpu = tf.distribute.cluster_resolver.TPUClusterResolver()  # TPU detection. No parameters necessary if TPU_NAME environment variable is set. On Kaggle this is always the case.\n",
    "    print('Running on TPU ', tpu.master())\n",
    "except ValueError:\n",
    "    tpu = None\n",
    "\n",
    "if tpu:\n",
    "    tf.config.experimental_connect_to_cluster(tpu)\n",
    "    tf.tpu.experimental.initialize_tpu_system(tpu)\n",
    "    strategy = tf.distribute.experimental.TPUStrategy(tpu)\n",
    "else:\n",
    "    strategy = tf.distribute.get_strategy() # default distribution strategy in Tensorflow. Works on CPU and single GPU.\n",
    "\n",
    "print(\"REPLICAS: \", strategy.num_replicas_in_sync)"
   ]
  },
  {
   "cell_type": "code",
   "execution_count": 17,
   "metadata": {},
   "outputs": [
    {
     "data": {
      "text/plain": [
       "[PhysicalDevice(name='/physical_device:CPU:0', device_type='CPU'),\n",
       " PhysicalDevice(name='/physical_device:GPU:0', device_type='GPU')]"
      ]
     },
     "execution_count": 17,
     "metadata": {},
     "output_type": "execute_result"
    }
   ],
   "source": [
    "tf.config.get_visible_devices()"
   ]
  },
  {
   "cell_type": "markdown",
   "metadata": {},
   "source": [
    "# Get my data path"
   ]
  },
  {
   "cell_type": "code",
   "execution_count": 14,
   "metadata": {
    "execution": {
     "iopub.execute_input": "2022-11-10T14:08:05.920175Z",
     "iopub.status.busy": "2022-11-10T14:08:05.919824Z",
     "iopub.status.idle": "2022-11-10T14:08:06.291257Z",
     "shell.execute_reply": "2022-11-10T14:08:06.290123Z",
     "shell.execute_reply.started": "2022-11-10T14:08:05.920140Z"
    }
   },
   "outputs": [],
   "source": [
    "#GCS_DS_PATH = KaggleDatasets().get_gcs_path() # you can list the bucket with \"!gsutil ls $GCS_DS_PATH\"\n",
    "GCS_DS_PATH = os.getcwd() + '/data/'"
   ]
  },
  {
   "cell_type": "markdown",
   "metadata": {},
   "source": [
    "# Set some parameters"
   ]
  },
  {
   "cell_type": "code",
   "execution_count": 15,
   "metadata": {
    "execution": {
     "iopub.execute_input": "2022-11-10T14:08:09.782518Z",
     "iopub.status.busy": "2022-11-10T14:08:09.782180Z",
     "iopub.status.idle": "2022-11-10T14:08:09.787934Z",
     "shell.execute_reply": "2022-11-10T14:08:09.786772Z",
     "shell.execute_reply.started": "2022-11-10T14:08:09.782483Z"
    }
   },
   "outputs": [],
   "source": [
    "IMAGE_SIZE = [192, 192] # at this size, a GPU will run out of memory. Use the TPU\n",
    "EPOCHS = 5\n",
    "BATCH_SIZE = 16 * strategy.num_replicas_in_sync\n",
    "\n",
    "NUM_TRAINING_IMAGES = 12753\n",
    "NUM_TEST_IMAGES = 7382\n",
    "STEPS_PER_EPOCH = NUM_TRAINING_IMAGES // BATCH_SIZE"
   ]
  },
  {
   "cell_type": "markdown",
   "metadata": {},
   "source": [
    "# Load my data\n",
    "\n",
    "This data is loaded from Kaggle and automatically sharded to maximize parallelization."
   ]
  },
  {
   "cell_type": "code",
   "execution_count": 16,
   "metadata": {
    "execution": {
     "iopub.execute_input": "2022-11-10T14:16:04.301101Z",
     "iopub.status.busy": "2022-11-10T14:16:04.300765Z",
     "iopub.status.idle": "2022-11-10T14:16:04.727296Z",
     "shell.execute_reply": "2022-11-10T14:16:04.726032Z",
     "shell.execute_reply.started": "2022-11-10T14:16:04.301071Z"
    }
   },
   "outputs": [
    {
     "name": "stderr",
     "output_type": "stream",
     "text": [
      "2022-11-13 14:50:25.734710: I tensorflow/stream_executor/cuda/cuda_gpu_executor.cc:980] successful NUMA node read from SysFS had negative value (-1), but there must be at least one NUMA node, so returning NUMA node zero\n",
      "2022-11-13 14:50:25.795613: I tensorflow/stream_executor/cuda/cuda_gpu_executor.cc:980] successful NUMA node read from SysFS had negative value (-1), but there must be at least one NUMA node, so returning NUMA node zero\n",
      "2022-11-13 14:50:25.796287: I tensorflow/stream_executor/cuda/cuda_gpu_executor.cc:980] successful NUMA node read from SysFS had negative value (-1), but there must be at least one NUMA node, so returning NUMA node zero\n",
      "2022-11-13 14:50:25.798625: I tensorflow/core/platform/cpu_feature_guard.cc:193] This TensorFlow binary is optimized with oneAPI Deep Neural Network Library (oneDNN) to use the following CPU instructions in performance-critical operations:  SSE4.1 SSE4.2 AVX AVX2 FMA\n",
      "To enable them in other operations, rebuild TensorFlow with the appropriate compiler flags.\n",
      "2022-11-13 14:50:25.799204: I tensorflow/stream_executor/cuda/cuda_gpu_executor.cc:980] successful NUMA node read from SysFS had negative value (-1), but there must be at least one NUMA node, so returning NUMA node zero\n",
      "2022-11-13 14:50:25.799785: I tensorflow/stream_executor/cuda/cuda_gpu_executor.cc:980] successful NUMA node read from SysFS had negative value (-1), but there must be at least one NUMA node, so returning NUMA node zero\n",
      "2022-11-13 14:50:25.800569: I tensorflow/stream_executor/cuda/cuda_gpu_executor.cc:980] successful NUMA node read from SysFS had negative value (-1), but there must be at least one NUMA node, so returning NUMA node zero\n",
      "2022-11-13 14:50:28.275121: I tensorflow/stream_executor/cuda/cuda_gpu_executor.cc:980] successful NUMA node read from SysFS had negative value (-1), but there must be at least one NUMA node, so returning NUMA node zero\n",
      "2022-11-13 14:50:28.275771: I tensorflow/stream_executor/cuda/cuda_gpu_executor.cc:980] successful NUMA node read from SysFS had negative value (-1), but there must be at least one NUMA node, so returning NUMA node zero\n",
      "2022-11-13 14:50:28.276227: I tensorflow/stream_executor/cuda/cuda_gpu_executor.cc:980] successful NUMA node read from SysFS had negative value (-1), but there must be at least one NUMA node, so returning NUMA node zero\n",
      "2022-11-13 14:50:28.276634: I tensorflow/core/common_runtime/gpu/gpu_device.cc:1616] Created device /job:localhost/replica:0/task:0/device:GPU:0 with 1442 MB memory:  -> device: 0, name: NVIDIA GeForce 840M, pci bus id: 0000:07:00.0, compute capability: 5.0\n"
     ]
    }
   ],
   "source": [
    "def decode_image(image_data):\n",
    "    image = tf.image.decode_jpeg(image_data, channels=3)\n",
    "    image = tf.cast(image, tf.float32) / 255.0  # convert image to floats in [0, 1] range\n",
    "    image = tf.reshape(image, [*IMAGE_SIZE, 3]) # explicit size needed for TPU\n",
    "    return image\n",
    "\n",
    "def read_labeled_tfrecord(example):\n",
    "    LABELED_TFREC_FORMAT = {\n",
    "        \"image\": tf.io.FixedLenFeature([], tf.string), # tf.string means bytestring\n",
    "        \"class\": tf.io.FixedLenFeature([], tf.int64),  # shape [] means single element\n",
    "    }\n",
    "    example = tf.io.parse_single_example(example, LABELED_TFREC_FORMAT)\n",
    "    image = decode_image(example['image'])\n",
    "    label = tf.cast(example['class'], tf.int32)\n",
    "    return image, label # returns a dataset of (image, label) pairs\n",
    "\n",
    "def read_unlabeled_tfrecord(example):\n",
    "    UNLABELED_TFREC_FORMAT = {\n",
    "        \"image\": tf.io.FixedLenFeature([], tf.string), # tf.string means bytestring\n",
    "        \"id\": tf.io.FixedLenFeature([], tf.string),  # shape [] means single element\n",
    "        # class is missing, this competitions's challenge is to predict flower classes for the test dataset\n",
    "    }\n",
    "    example = tf.io.parse_single_example(example, UNLABELED_TFREC_FORMAT)\n",
    "    image = decode_image(example['image'])\n",
    "    idnum = example['id']\n",
    "    return image, idnum # returns a dataset of image(s)\n",
    "\n",
    "def load_dataset(filenames, labeled=True, ordered=False):\n",
    "    # Read from TFRecords. For optimal performance, reading from multiple files at once and\n",
    "    # disregarding data order. Order does not matter since we will be shuffling the data anyway.\n",
    "\n",
    "    ignore_order = tf.data.Options()\n",
    "    if not ordered:\n",
    "        ignore_order.experimental_deterministic = False # disable order, increase speed\n",
    "\n",
    "    dataset = tf.data.TFRecordDataset(filenames) # automatically interleaves reads from multiple files\n",
    "    dataset = dataset.with_options(ignore_order) # uses data as soon as it streams in, rather than in its original order\n",
    "    dataset = dataset.map(read_labeled_tfrecord if labeled else read_unlabeled_tfrecord)\n",
    "    # returns a dataset of (image, label) pairs if labeled=True or (image, id) pairs if labeled=False\n",
    "    return dataset\n",
    "\n",
    "def get_training_dataset():\n",
    "    dataset = load_dataset(tf.io.gfile.glob(GCS_DS_PATH + '/tfrecords-jpeg-192x192/train/*.tfrec'), labeled=True)\n",
    "    dataset = dataset.repeat() # the training dataset must repeat for several epochs\n",
    "    dataset = dataset.shuffle(2048)\n",
    "    dataset = dataset.batch(BATCH_SIZE)\n",
    "    return dataset\n",
    "\n",
    "def get_validation_dataset():\n",
    "    dataset = load_dataset(tf.io.gfile.glob(GCS_DS_PATH + '/tfrecords-jpeg-192x192/val/*.tfrec'), labeled=True, ordered=False)\n",
    "    dataset = dataset.batch(BATCH_SIZE)\n",
    "    dataset = dataset.cache()\n",
    "    return dataset\n",
    "\n",
    "def get_test_dataset(ordered=False):\n",
    "    dataset = load_dataset(tf.io.gfile.glob(GCS_DS_PATH + '/tfrecords-jpeg-192x192/test/*.tfrec'), labeled=False, ordered=ordered)\n",
    "    dataset = dataset.batch(BATCH_SIZE)\n",
    "    return dataset\n",
    "\n",
    "training_dataset = get_training_dataset()\n",
    "validation_dataset = get_validation_dataset()"
   ]
  },
  {
   "cell_type": "markdown",
   "metadata": {},
   "source": [
    "# Build a model on TPU (or GPU, or CPU...) with Tensorflow 2.1!"
   ]
  },
  {
   "cell_type": "code",
   "execution_count": 20,
   "metadata": {},
   "outputs": [
    {
     "name": "stdout",
     "output_type": "stream",
     "text": [
      "Epoch 1/5\n"
     ]
    },
    {
     "name": "stderr",
     "output_type": "stream",
     "text": [
      "2022-11-13 14:55:05.845264: E tensorflow/stream_executor/cuda/cuda_blas.cc:218] failed to create cublas handle: cublas error\n",
      "2022-11-13 14:55:05.845348: W tensorflow/core/kernels/conv_ops_gpu.cc:204] None of the algorithms provided by cuDNN frontend heuristics worked; trying fallback algorithms.  Conv: batch: 16\n",
      "in_depths: 3\n",
      "out_depths: 64\n",
      "in: 192\n",
      "in: 192\n",
      "data_format: 1\n",
      "filter: 3\n",
      "filter: 3\n",
      "filter: 3\n",
      "dilation: 1\n",
      "dilation: 1\n",
      "stride: 1\n",
      "stride: 1\n",
      "padding: 1\n",
      "padding: 1\n",
      "dtype: DT_FLOAT\n",
      "group_count: 1\n",
      "device_identifier: \"NVIDIA GeForce 840M sm_5.0 with 2101870592B RAM and 3 cores\"\n",
      "fusion {\n",
      "  activation_mode: kRelu\n",
      "  conv_scale: 1\n",
      "}\n",
      "version: 1\n",
      "\n",
      "2022-11-13 14:55:05.853114: E tensorflow/stream_executor/cuda/cuda_blas.cc:218] failed to create cublas handle: cublas error\n",
      "2022-11-13 14:55:05.853251: W tensorflow/core/framework/op_kernel.cc:1780] OP_REQUIRES failed at conv_ops_fused_impl.h:601 : NOT_FOUND: No algorithm worked!  Error messages:\n",
      "  Profiling failure on CUDNN engine eng11{}: UNKNOWN: CUDNN_STATUS_ALLOC_FAILED\n",
      "in tensorflow/stream_executor/cuda/cuda_dnn.cc(4369): 'status'\n",
      "  Profiling failure on CUDNN engine eng0{}: UNKNOWN: CUDNN_STATUS_ALLOC_FAILED\n",
      "in tensorflow/stream_executor/cuda/cuda_dnn.cc(4369): 'status'\n"
     ]
    },
    {
     "ename": "NotFoundError",
     "evalue": "Graph execution error:\n\nDetected at node 'sequential_2/vgg16/block1_conv1/Relu' defined at (most recent call last):\n    File \"/home/pib73/anaconda3/envs/with_TF_2_10/lib/python3.10/runpy.py\", line 196, in _run_module_as_main\n      return _run_code(code, main_globals, None,\n    File \"/home/pib73/anaconda3/envs/with_TF_2_10/lib/python3.10/runpy.py\", line 86, in _run_code\n      exec(code, run_globals)\n    File \"/home/pib73/anaconda3/envs/with_TF_2_10/lib/python3.10/site-packages/ipykernel_launcher.py\", line 17, in <module>\n      app.launch_new_instance()\n    File \"/home/pib73/anaconda3/envs/with_TF_2_10/lib/python3.10/site-packages/traitlets/config/application.py\", line 982, in launch_instance\n      app.start()\n    File \"/home/pib73/anaconda3/envs/with_TF_2_10/lib/python3.10/site-packages/ipykernel/kernelapp.py\", line 712, in start\n      self.io_loop.start()\n    File \"/home/pib73/anaconda3/envs/with_TF_2_10/lib/python3.10/site-packages/tornado/platform/asyncio.py\", line 215, in start\n      self.asyncio_loop.run_forever()\n    File \"/home/pib73/anaconda3/envs/with_TF_2_10/lib/python3.10/asyncio/base_events.py\", line 600, in run_forever\n      self._run_once()\n    File \"/home/pib73/anaconda3/envs/with_TF_2_10/lib/python3.10/asyncio/base_events.py\", line 1896, in _run_once\n      handle._run()\n    File \"/home/pib73/anaconda3/envs/with_TF_2_10/lib/python3.10/asyncio/events.py\", line 80, in _run\n      self._context.run(self._callback, *self._args)\n    File \"/home/pib73/anaconda3/envs/with_TF_2_10/lib/python3.10/site-packages/ipykernel/kernelbase.py\", line 510, in dispatch_queue\n      await self.process_one()\n    File \"/home/pib73/anaconda3/envs/with_TF_2_10/lib/python3.10/site-packages/ipykernel/kernelbase.py\", line 499, in process_one\n      await dispatch(*args)\n    File \"/home/pib73/anaconda3/envs/with_TF_2_10/lib/python3.10/site-packages/ipykernel/kernelbase.py\", line 406, in dispatch_shell\n      await result\n    File \"/home/pib73/anaconda3/envs/with_TF_2_10/lib/python3.10/site-packages/ipykernel/kernelbase.py\", line 730, in execute_request\n      reply_content = await reply_content\n    File \"/home/pib73/anaconda3/envs/with_TF_2_10/lib/python3.10/site-packages/ipykernel/ipkernel.py\", line 383, in do_execute\n      res = shell.run_cell(\n    File \"/home/pib73/anaconda3/envs/with_TF_2_10/lib/python3.10/site-packages/ipykernel/zmqshell.py\", line 528, in run_cell\n      return super().run_cell(*args, **kwargs)\n    File \"/home/pib73/anaconda3/envs/with_TF_2_10/lib/python3.10/site-packages/IPython/core/interactiveshell.py\", line 2940, in run_cell\n      result = self._run_cell(\n    File \"/home/pib73/anaconda3/envs/with_TF_2_10/lib/python3.10/site-packages/IPython/core/interactiveshell.py\", line 2995, in _run_cell\n      return runner(coro)\n    File \"/home/pib73/anaconda3/envs/with_TF_2_10/lib/python3.10/site-packages/IPython/core/async_helpers.py\", line 129, in _pseudo_sync_runner\n      coro.send(None)\n    File \"/home/pib73/anaconda3/envs/with_TF_2_10/lib/python3.10/site-packages/IPython/core/interactiveshell.py\", line 3194, in run_cell_async\n      has_raised = await self.run_ast_nodes(code_ast.body, cell_name,\n    File \"/home/pib73/anaconda3/envs/with_TF_2_10/lib/python3.10/site-packages/IPython/core/interactiveshell.py\", line 3373, in run_ast_nodes\n      if await self.run_code(code, result, async_=asy):\n    File \"/home/pib73/anaconda3/envs/with_TF_2_10/lib/python3.10/site-packages/IPython/core/interactiveshell.py\", line 3433, in run_code\n      exec(code_obj, self.user_global_ns, self.user_ns)\n    File \"/tmp/ipykernel_31911/1499286688.py\", line 19, in <module>\n      historical = model.fit(training_dataset,\n    File \"/home/pib73/anaconda3/envs/with_TF_2_10/lib/python3.10/site-packages/keras/utils/traceback_utils.py\", line 65, in error_handler\n      return fn(*args, **kwargs)\n    File \"/home/pib73/anaconda3/envs/with_TF_2_10/lib/python3.10/site-packages/keras/engine/training.py\", line 1564, in fit\n      tmp_logs = self.train_function(iterator)\n    File \"/home/pib73/anaconda3/envs/with_TF_2_10/lib/python3.10/site-packages/keras/engine/training.py\", line 1160, in train_function\n      return step_function(self, iterator)\n    File \"/home/pib73/anaconda3/envs/with_TF_2_10/lib/python3.10/site-packages/keras/engine/training.py\", line 1146, in step_function\n      outputs = model.distribute_strategy.run(run_step, args=(data,))\n    File \"/home/pib73/anaconda3/envs/with_TF_2_10/lib/python3.10/site-packages/keras/engine/training.py\", line 1135, in run_step\n      outputs = model.train_step(data)\n    File \"/home/pib73/anaconda3/envs/with_TF_2_10/lib/python3.10/site-packages/keras/engine/training.py\", line 993, in train_step\n      y_pred = self(x, training=True)\n    File \"/home/pib73/anaconda3/envs/with_TF_2_10/lib/python3.10/site-packages/keras/utils/traceback_utils.py\", line 65, in error_handler\n      return fn(*args, **kwargs)\n    File \"/home/pib73/anaconda3/envs/with_TF_2_10/lib/python3.10/site-packages/keras/engine/training.py\", line 557, in __call__\n      return super().__call__(*args, **kwargs)\n    File \"/home/pib73/anaconda3/envs/with_TF_2_10/lib/python3.10/site-packages/keras/utils/traceback_utils.py\", line 65, in error_handler\n      return fn(*args, **kwargs)\n    File \"/home/pib73/anaconda3/envs/with_TF_2_10/lib/python3.10/site-packages/keras/engine/base_layer.py\", line 1097, in __call__\n      outputs = call_fn(inputs, *args, **kwargs)\n    File \"/home/pib73/anaconda3/envs/with_TF_2_10/lib/python3.10/site-packages/keras/utils/traceback_utils.py\", line 96, in error_handler\n      return fn(*args, **kwargs)\n    File \"/home/pib73/anaconda3/envs/with_TF_2_10/lib/python3.10/site-packages/keras/engine/sequential.py\", line 410, in call\n      return super().call(inputs, training=training, mask=mask)\n    File \"/home/pib73/anaconda3/envs/with_TF_2_10/lib/python3.10/site-packages/keras/engine/functional.py\", line 510, in call\n      return self._run_internal_graph(inputs, training=training, mask=mask)\n    File \"/home/pib73/anaconda3/envs/with_TF_2_10/lib/python3.10/site-packages/keras/engine/functional.py\", line 667, in _run_internal_graph\n      outputs = node.layer(*args, **kwargs)\n    File \"/home/pib73/anaconda3/envs/with_TF_2_10/lib/python3.10/site-packages/keras/utils/traceback_utils.py\", line 65, in error_handler\n      return fn(*args, **kwargs)\n    File \"/home/pib73/anaconda3/envs/with_TF_2_10/lib/python3.10/site-packages/keras/engine/training.py\", line 557, in __call__\n      return super().__call__(*args, **kwargs)\n    File \"/home/pib73/anaconda3/envs/with_TF_2_10/lib/python3.10/site-packages/keras/utils/traceback_utils.py\", line 65, in error_handler\n      return fn(*args, **kwargs)\n    File \"/home/pib73/anaconda3/envs/with_TF_2_10/lib/python3.10/site-packages/keras/engine/base_layer.py\", line 1097, in __call__\n      outputs = call_fn(inputs, *args, **kwargs)\n    File \"/home/pib73/anaconda3/envs/with_TF_2_10/lib/python3.10/site-packages/keras/utils/traceback_utils.py\", line 96, in error_handler\n      return fn(*args, **kwargs)\n    File \"/home/pib73/anaconda3/envs/with_TF_2_10/lib/python3.10/site-packages/keras/engine/functional.py\", line 510, in call\n      return self._run_internal_graph(inputs, training=training, mask=mask)\n    File \"/home/pib73/anaconda3/envs/with_TF_2_10/lib/python3.10/site-packages/keras/engine/functional.py\", line 667, in _run_internal_graph\n      outputs = node.layer(*args, **kwargs)\n    File \"/home/pib73/anaconda3/envs/with_TF_2_10/lib/python3.10/site-packages/keras/utils/traceback_utils.py\", line 65, in error_handler\n      return fn(*args, **kwargs)\n    File \"/home/pib73/anaconda3/envs/with_TF_2_10/lib/python3.10/site-packages/keras/engine/base_layer.py\", line 1097, in __call__\n      outputs = call_fn(inputs, *args, **kwargs)\n    File \"/home/pib73/anaconda3/envs/with_TF_2_10/lib/python3.10/site-packages/keras/utils/traceback_utils.py\", line 96, in error_handler\n      return fn(*args, **kwargs)\n    File \"/home/pib73/anaconda3/envs/with_TF_2_10/lib/python3.10/site-packages/keras/layers/convolutional/base_conv.py\", line 314, in call\n      return self.activation(outputs)\n    File \"/home/pib73/anaconda3/envs/with_TF_2_10/lib/python3.10/site-packages/keras/activations.py\", line 317, in relu\n      return backend.relu(\n    File \"/home/pib73/anaconda3/envs/with_TF_2_10/lib/python3.10/site-packages/keras/backend.py\", line 5366, in relu\n      x = tf.nn.relu(x)\nNode: 'sequential_2/vgg16/block1_conv1/Relu'\nNo algorithm worked!  Error messages:\n  Profiling failure on CUDNN engine eng11{}: UNKNOWN: CUDNN_STATUS_ALLOC_FAILED\nin tensorflow/stream_executor/cuda/cuda_dnn.cc(4369): 'status'\n  Profiling failure on CUDNN engine eng0{}: UNKNOWN: CUDNN_STATUS_ALLOC_FAILED\nin tensorflow/stream_executor/cuda/cuda_dnn.cc(4369): 'status'\n\t [[{{node sequential_2/vgg16/block1_conv1/Relu}}]] [Op:__inference_train_function_4198]",
     "output_type": "error",
     "traceback": [
      "\u001b[0;31m---------------------------------------------------------------------------\u001b[0m",
      "\u001b[0;31mNotFoundError\u001b[0m                             Traceback (most recent call last)",
      "Cell \u001b[0;32mIn [20], line 19\u001b[0m\n\u001b[1;32m     11\u001b[0m f1_score \u001b[38;5;241m=\u001b[39m tfa\u001b[38;5;241m.\u001b[39mmetrics\u001b[38;5;241m.\u001b[39mF1Score(\u001b[38;5;241m104\u001b[39m, \u001b[38;5;124m'\u001b[39m\u001b[38;5;124mmacro\u001b[39m\u001b[38;5;124m'\u001b[39m)\n\u001b[1;32m     13\u001b[0m model\u001b[38;5;241m.\u001b[39mcompile(\n\u001b[1;32m     14\u001b[0m     optimizer\u001b[38;5;241m=\u001b[39m\u001b[38;5;124m'\u001b[39m\u001b[38;5;124madam\u001b[39m\u001b[38;5;124m'\u001b[39m,\n\u001b[1;32m     15\u001b[0m     loss \u001b[38;5;241m=\u001b[39m \u001b[38;5;124m'\u001b[39m\u001b[38;5;124msparse_categorical_crossentropy\u001b[39m\u001b[38;5;124m'\u001b[39m,\n\u001b[1;32m     16\u001b[0m     metrics\u001b[38;5;241m=\u001b[39m[\u001b[38;5;124m'\u001b[39m\u001b[38;5;124msparse_categorical_accuracy\u001b[39m\u001b[38;5;124m'\u001b[39m]\n\u001b[1;32m     17\u001b[0m )\n\u001b[0;32m---> 19\u001b[0m historical \u001b[38;5;241m=\u001b[39m \u001b[43mmodel\u001b[49m\u001b[38;5;241;43m.\u001b[39;49m\u001b[43mfit\u001b[49m\u001b[43m(\u001b[49m\u001b[43mtraining_dataset\u001b[49m\u001b[43m,\u001b[49m\u001b[43m \u001b[49m\n\u001b[1;32m     20\u001b[0m \u001b[43m          \u001b[49m\u001b[43msteps_per_epoch\u001b[49m\u001b[38;5;241;43m=\u001b[39;49m\u001b[43mSTEPS_PER_EPOCH\u001b[49m\u001b[43m,\u001b[49m\u001b[43m \u001b[49m\n\u001b[1;32m     21\u001b[0m \u001b[43m          \u001b[49m\u001b[43mepochs\u001b[49m\u001b[38;5;241;43m=\u001b[39;49m\u001b[43mEPOCHS\u001b[49m\u001b[43m,\u001b[49m\u001b[43m \u001b[49m\n\u001b[1;32m     22\u001b[0m \u001b[43m          \u001b[49m\u001b[43mvalidation_data\u001b[49m\u001b[38;5;241;43m=\u001b[39;49m\u001b[43mvalidation_dataset\u001b[49m\u001b[43m)\u001b[49m\n",
      "File \u001b[0;32m~/anaconda3/envs/with_TF_2_10/lib/python3.10/site-packages/keras/utils/traceback_utils.py:70\u001b[0m, in \u001b[0;36mfilter_traceback.<locals>.error_handler\u001b[0;34m(*args, **kwargs)\u001b[0m\n\u001b[1;32m     67\u001b[0m     filtered_tb \u001b[38;5;241m=\u001b[39m _process_traceback_frames(e\u001b[38;5;241m.\u001b[39m__traceback__)\n\u001b[1;32m     68\u001b[0m     \u001b[38;5;66;03m# To get the full stack trace, call:\u001b[39;00m\n\u001b[1;32m     69\u001b[0m     \u001b[38;5;66;03m# `tf.debugging.disable_traceback_filtering()`\u001b[39;00m\n\u001b[0;32m---> 70\u001b[0m     \u001b[38;5;28;01mraise\u001b[39;00m e\u001b[38;5;241m.\u001b[39mwith_traceback(filtered_tb) \u001b[38;5;28;01mfrom\u001b[39;00m \u001b[38;5;28mNone\u001b[39m\n\u001b[1;32m     71\u001b[0m \u001b[38;5;28;01mfinally\u001b[39;00m:\n\u001b[1;32m     72\u001b[0m     \u001b[38;5;28;01mdel\u001b[39;00m filtered_tb\n",
      "File \u001b[0;32m~/anaconda3/envs/with_TF_2_10/lib/python3.10/site-packages/tensorflow/python/eager/execute.py:54\u001b[0m, in \u001b[0;36mquick_execute\u001b[0;34m(op_name, num_outputs, inputs, attrs, ctx, name)\u001b[0m\n\u001b[1;32m     52\u001b[0m \u001b[38;5;28;01mtry\u001b[39;00m:\n\u001b[1;32m     53\u001b[0m   ctx\u001b[38;5;241m.\u001b[39mensure_initialized()\n\u001b[0;32m---> 54\u001b[0m   tensors \u001b[38;5;241m=\u001b[39m pywrap_tfe\u001b[38;5;241m.\u001b[39mTFE_Py_Execute(ctx\u001b[38;5;241m.\u001b[39m_handle, device_name, op_name,\n\u001b[1;32m     55\u001b[0m                                       inputs, attrs, num_outputs)\n\u001b[1;32m     56\u001b[0m \u001b[38;5;28;01mexcept\u001b[39;00m core\u001b[38;5;241m.\u001b[39m_NotOkStatusException \u001b[38;5;28;01mas\u001b[39;00m e:\n\u001b[1;32m     57\u001b[0m   \u001b[38;5;28;01mif\u001b[39;00m name \u001b[38;5;129;01mis\u001b[39;00m \u001b[38;5;129;01mnot\u001b[39;00m \u001b[38;5;28;01mNone\u001b[39;00m:\n",
      "\u001b[0;31mNotFoundError\u001b[0m: Graph execution error:\n\nDetected at node 'sequential_2/vgg16/block1_conv1/Relu' defined at (most recent call last):\n    File \"/home/pib73/anaconda3/envs/with_TF_2_10/lib/python3.10/runpy.py\", line 196, in _run_module_as_main\n      return _run_code(code, main_globals, None,\n    File \"/home/pib73/anaconda3/envs/with_TF_2_10/lib/python3.10/runpy.py\", line 86, in _run_code\n      exec(code, run_globals)\n    File \"/home/pib73/anaconda3/envs/with_TF_2_10/lib/python3.10/site-packages/ipykernel_launcher.py\", line 17, in <module>\n      app.launch_new_instance()\n    File \"/home/pib73/anaconda3/envs/with_TF_2_10/lib/python3.10/site-packages/traitlets/config/application.py\", line 982, in launch_instance\n      app.start()\n    File \"/home/pib73/anaconda3/envs/with_TF_2_10/lib/python3.10/site-packages/ipykernel/kernelapp.py\", line 712, in start\n      self.io_loop.start()\n    File \"/home/pib73/anaconda3/envs/with_TF_2_10/lib/python3.10/site-packages/tornado/platform/asyncio.py\", line 215, in start\n      self.asyncio_loop.run_forever()\n    File \"/home/pib73/anaconda3/envs/with_TF_2_10/lib/python3.10/asyncio/base_events.py\", line 600, in run_forever\n      self._run_once()\n    File \"/home/pib73/anaconda3/envs/with_TF_2_10/lib/python3.10/asyncio/base_events.py\", line 1896, in _run_once\n      handle._run()\n    File \"/home/pib73/anaconda3/envs/with_TF_2_10/lib/python3.10/asyncio/events.py\", line 80, in _run\n      self._context.run(self._callback, *self._args)\n    File \"/home/pib73/anaconda3/envs/with_TF_2_10/lib/python3.10/site-packages/ipykernel/kernelbase.py\", line 510, in dispatch_queue\n      await self.process_one()\n    File \"/home/pib73/anaconda3/envs/with_TF_2_10/lib/python3.10/site-packages/ipykernel/kernelbase.py\", line 499, in process_one\n      await dispatch(*args)\n    File \"/home/pib73/anaconda3/envs/with_TF_2_10/lib/python3.10/site-packages/ipykernel/kernelbase.py\", line 406, in dispatch_shell\n      await result\n    File \"/home/pib73/anaconda3/envs/with_TF_2_10/lib/python3.10/site-packages/ipykernel/kernelbase.py\", line 730, in execute_request\n      reply_content = await reply_content\n    File \"/home/pib73/anaconda3/envs/with_TF_2_10/lib/python3.10/site-packages/ipykernel/ipkernel.py\", line 383, in do_execute\n      res = shell.run_cell(\n    File \"/home/pib73/anaconda3/envs/with_TF_2_10/lib/python3.10/site-packages/ipykernel/zmqshell.py\", line 528, in run_cell\n      return super().run_cell(*args, **kwargs)\n    File \"/home/pib73/anaconda3/envs/with_TF_2_10/lib/python3.10/site-packages/IPython/core/interactiveshell.py\", line 2940, in run_cell\n      result = self._run_cell(\n    File \"/home/pib73/anaconda3/envs/with_TF_2_10/lib/python3.10/site-packages/IPython/core/interactiveshell.py\", line 2995, in _run_cell\n      return runner(coro)\n    File \"/home/pib73/anaconda3/envs/with_TF_2_10/lib/python3.10/site-packages/IPython/core/async_helpers.py\", line 129, in _pseudo_sync_runner\n      coro.send(None)\n    File \"/home/pib73/anaconda3/envs/with_TF_2_10/lib/python3.10/site-packages/IPython/core/interactiveshell.py\", line 3194, in run_cell_async\n      has_raised = await self.run_ast_nodes(code_ast.body, cell_name,\n    File \"/home/pib73/anaconda3/envs/with_TF_2_10/lib/python3.10/site-packages/IPython/core/interactiveshell.py\", line 3373, in run_ast_nodes\n      if await self.run_code(code, result, async_=asy):\n    File \"/home/pib73/anaconda3/envs/with_TF_2_10/lib/python3.10/site-packages/IPython/core/interactiveshell.py\", line 3433, in run_code\n      exec(code_obj, self.user_global_ns, self.user_ns)\n    File \"/tmp/ipykernel_31911/1499286688.py\", line 19, in <module>\n      historical = model.fit(training_dataset,\n    File \"/home/pib73/anaconda3/envs/with_TF_2_10/lib/python3.10/site-packages/keras/utils/traceback_utils.py\", line 65, in error_handler\n      return fn(*args, **kwargs)\n    File \"/home/pib73/anaconda3/envs/with_TF_2_10/lib/python3.10/site-packages/keras/engine/training.py\", line 1564, in fit\n      tmp_logs = self.train_function(iterator)\n    File \"/home/pib73/anaconda3/envs/with_TF_2_10/lib/python3.10/site-packages/keras/engine/training.py\", line 1160, in train_function\n      return step_function(self, iterator)\n    File \"/home/pib73/anaconda3/envs/with_TF_2_10/lib/python3.10/site-packages/keras/engine/training.py\", line 1146, in step_function\n      outputs = model.distribute_strategy.run(run_step, args=(data,))\n    File \"/home/pib73/anaconda3/envs/with_TF_2_10/lib/python3.10/site-packages/keras/engine/training.py\", line 1135, in run_step\n      outputs = model.train_step(data)\n    File \"/home/pib73/anaconda3/envs/with_TF_2_10/lib/python3.10/site-packages/keras/engine/training.py\", line 993, in train_step\n      y_pred = self(x, training=True)\n    File \"/home/pib73/anaconda3/envs/with_TF_2_10/lib/python3.10/site-packages/keras/utils/traceback_utils.py\", line 65, in error_handler\n      return fn(*args, **kwargs)\n    File \"/home/pib73/anaconda3/envs/with_TF_2_10/lib/python3.10/site-packages/keras/engine/training.py\", line 557, in __call__\n      return super().__call__(*args, **kwargs)\n    File \"/home/pib73/anaconda3/envs/with_TF_2_10/lib/python3.10/site-packages/keras/utils/traceback_utils.py\", line 65, in error_handler\n      return fn(*args, **kwargs)\n    File \"/home/pib73/anaconda3/envs/with_TF_2_10/lib/python3.10/site-packages/keras/engine/base_layer.py\", line 1097, in __call__\n      outputs = call_fn(inputs, *args, **kwargs)\n    File \"/home/pib73/anaconda3/envs/with_TF_2_10/lib/python3.10/site-packages/keras/utils/traceback_utils.py\", line 96, in error_handler\n      return fn(*args, **kwargs)\n    File \"/home/pib73/anaconda3/envs/with_TF_2_10/lib/python3.10/site-packages/keras/engine/sequential.py\", line 410, in call\n      return super().call(inputs, training=training, mask=mask)\n    File \"/home/pib73/anaconda3/envs/with_TF_2_10/lib/python3.10/site-packages/keras/engine/functional.py\", line 510, in call\n      return self._run_internal_graph(inputs, training=training, mask=mask)\n    File \"/home/pib73/anaconda3/envs/with_TF_2_10/lib/python3.10/site-packages/keras/engine/functional.py\", line 667, in _run_internal_graph\n      outputs = node.layer(*args, **kwargs)\n    File \"/home/pib73/anaconda3/envs/with_TF_2_10/lib/python3.10/site-packages/keras/utils/traceback_utils.py\", line 65, in error_handler\n      return fn(*args, **kwargs)\n    File \"/home/pib73/anaconda3/envs/with_TF_2_10/lib/python3.10/site-packages/keras/engine/training.py\", line 557, in __call__\n      return super().__call__(*args, **kwargs)\n    File \"/home/pib73/anaconda3/envs/with_TF_2_10/lib/python3.10/site-packages/keras/utils/traceback_utils.py\", line 65, in error_handler\n      return fn(*args, **kwargs)\n    File \"/home/pib73/anaconda3/envs/with_TF_2_10/lib/python3.10/site-packages/keras/engine/base_layer.py\", line 1097, in __call__\n      outputs = call_fn(inputs, *args, **kwargs)\n    File \"/home/pib73/anaconda3/envs/with_TF_2_10/lib/python3.10/site-packages/keras/utils/traceback_utils.py\", line 96, in error_handler\n      return fn(*args, **kwargs)\n    File \"/home/pib73/anaconda3/envs/with_TF_2_10/lib/python3.10/site-packages/keras/engine/functional.py\", line 510, in call\n      return self._run_internal_graph(inputs, training=training, mask=mask)\n    File \"/home/pib73/anaconda3/envs/with_TF_2_10/lib/python3.10/site-packages/keras/engine/functional.py\", line 667, in _run_internal_graph\n      outputs = node.layer(*args, **kwargs)\n    File \"/home/pib73/anaconda3/envs/with_TF_2_10/lib/python3.10/site-packages/keras/utils/traceback_utils.py\", line 65, in error_handler\n      return fn(*args, **kwargs)\n    File \"/home/pib73/anaconda3/envs/with_TF_2_10/lib/python3.10/site-packages/keras/engine/base_layer.py\", line 1097, in __call__\n      outputs = call_fn(inputs, *args, **kwargs)\n    File \"/home/pib73/anaconda3/envs/with_TF_2_10/lib/python3.10/site-packages/keras/utils/traceback_utils.py\", line 96, in error_handler\n      return fn(*args, **kwargs)\n    File \"/home/pib73/anaconda3/envs/with_TF_2_10/lib/python3.10/site-packages/keras/layers/convolutional/base_conv.py\", line 314, in call\n      return self.activation(outputs)\n    File \"/home/pib73/anaconda3/envs/with_TF_2_10/lib/python3.10/site-packages/keras/activations.py\", line 317, in relu\n      return backend.relu(\n    File \"/home/pib73/anaconda3/envs/with_TF_2_10/lib/python3.10/site-packages/keras/backend.py\", line 5366, in relu\n      x = tf.nn.relu(x)\nNode: 'sequential_2/vgg16/block1_conv1/Relu'\nNo algorithm worked!  Error messages:\n  Profiling failure on CUDNN engine eng11{}: UNKNOWN: CUDNN_STATUS_ALLOC_FAILED\nin tensorflow/stream_executor/cuda/cuda_dnn.cc(4369): 'status'\n  Profiling failure on CUDNN engine eng0{}: UNKNOWN: CUDNN_STATUS_ALLOC_FAILED\nin tensorflow/stream_executor/cuda/cuda_dnn.cc(4369): 'status'\n\t [[{{node sequential_2/vgg16/block1_conv1/Relu}}]] [Op:__inference_train_function_4198]"
     ]
    }
   ],
   "source": [
    "# with strategy.scope():    \n",
    "pretrained_model = tf.keras.applications.VGG16(weights='imagenet', include_top=False ,input_shape=[*IMAGE_SIZE, 3])\n",
    "pretrained_model.trainable = False # tramsfer learning\n",
    "\n",
    "model = tf.keras.Sequential([\n",
    "    pretrained_model,\n",
    "    tf.keras.layers.GlobalAveragePooling2D(),\n",
    "    tf.keras.layers.Dense(104, activation='softmax')\n",
    "])\n",
    "\n",
    "f1_score = tfa.metrics.F1Score(104, 'macro')\n",
    "        \n",
    "model.compile(\n",
    "    optimizer='adam',\n",
    "    loss = 'sparse_categorical_crossentropy',\n",
    "    metrics=['sparse_categorical_accuracy']\n",
    ")\n",
    "\n",
    "historical = model.fit(training_dataset, \n",
    "          steps_per_epoch=STEPS_PER_EPOCH, \n",
    "          epochs=EPOCHS, \n",
    "          validation_data=validation_dataset)"
   ]
  },
  {
   "cell_type": "code",
   "execution_count": 19,
   "metadata": {
    "execution": {
     "iopub.execute_input": "2022-11-10T14:22:56.908357Z",
     "iopub.status.busy": "2022-11-10T14:22:56.908014Z",
     "iopub.status.idle": "2022-11-10T14:22:59.672342Z",
     "shell.execute_reply": "2022-11-10T14:22:59.670815Z",
     "shell.execute_reply.started": "2022-11-10T14:22:56.908324Z"
    }
   },
   "outputs": [
    {
     "name": "stdout",
     "output_type": "stream",
     "text": [
      "Epoch 1/5\n"
     ]
    },
    {
     "name": "stderr",
     "output_type": "stream",
     "text": [
      "2022-11-13 14:52:45.090354: E tensorflow/stream_executor/cuda/cuda_blas.cc:218] failed to create cublas handle: cublas error\n",
      "2022-11-13 14:52:45.090433: W tensorflow/core/kernels/conv_ops_gpu.cc:204] None of the algorithms provided by cuDNN frontend heuristics worked; trying fallback algorithms.  Conv: batch: 16\n",
      "in_depths: 3\n",
      "out_depths: 64\n",
      "in: 192\n",
      "in: 192\n",
      "data_format: 1\n",
      "filter: 3\n",
      "filter: 3\n",
      "filter: 3\n",
      "dilation: 1\n",
      "dilation: 1\n",
      "stride: 1\n",
      "stride: 1\n",
      "padding: 1\n",
      "padding: 1\n",
      "dtype: DT_FLOAT\n",
      "group_count: 1\n",
      "device_identifier: \"NVIDIA GeForce 840M sm_5.0 with 2101870592B RAM and 3 cores\"\n",
      "fusion {\n",
      "  activation_mode: kRelu\n",
      "  conv_scale: 1\n",
      "}\n",
      "version: 1\n",
      "\n",
      "2022-11-13 14:52:45.098150: E tensorflow/stream_executor/cuda/cuda_blas.cc:218] failed to create cublas handle: cublas error\n",
      "2022-11-13 14:52:45.098261: W tensorflow/core/framework/op_kernel.cc:1780] OP_REQUIRES failed at conv_ops_fused_impl.h:601 : NOT_FOUND: No algorithm worked!  Error messages:\n",
      "  Profiling failure on CUDNN engine eng11{}: UNKNOWN: CUDNN_STATUS_ALLOC_FAILED\n",
      "in tensorflow/stream_executor/cuda/cuda_dnn.cc(4369): 'status'\n",
      "  Profiling failure on CUDNN engine eng0{}: UNKNOWN: CUDNN_STATUS_ALLOC_FAILED\n",
      "in tensorflow/stream_executor/cuda/cuda_dnn.cc(4369): 'status'\n"
     ]
    },
    {
     "ename": "NotFoundError",
     "evalue": "Graph execution error:\n\nDetected at node 'sequential_1/vgg16/block1_conv1/Relu' defined at (most recent call last):\n    File \"/home/pib73/anaconda3/envs/with_TF_2_10/lib/python3.10/runpy.py\", line 196, in _run_module_as_main\n      return _run_code(code, main_globals, None,\n    File \"/home/pib73/anaconda3/envs/with_TF_2_10/lib/python3.10/runpy.py\", line 86, in _run_code\n      exec(code, run_globals)\n    File \"/home/pib73/anaconda3/envs/with_TF_2_10/lib/python3.10/site-packages/ipykernel_launcher.py\", line 17, in <module>\n      app.launch_new_instance()\n    File \"/home/pib73/anaconda3/envs/with_TF_2_10/lib/python3.10/site-packages/traitlets/config/application.py\", line 982, in launch_instance\n      app.start()\n    File \"/home/pib73/anaconda3/envs/with_TF_2_10/lib/python3.10/site-packages/ipykernel/kernelapp.py\", line 712, in start\n      self.io_loop.start()\n    File \"/home/pib73/anaconda3/envs/with_TF_2_10/lib/python3.10/site-packages/tornado/platform/asyncio.py\", line 215, in start\n      self.asyncio_loop.run_forever()\n    File \"/home/pib73/anaconda3/envs/with_TF_2_10/lib/python3.10/asyncio/base_events.py\", line 600, in run_forever\n      self._run_once()\n    File \"/home/pib73/anaconda3/envs/with_TF_2_10/lib/python3.10/asyncio/base_events.py\", line 1896, in _run_once\n      handle._run()\n    File \"/home/pib73/anaconda3/envs/with_TF_2_10/lib/python3.10/asyncio/events.py\", line 80, in _run\n      self._context.run(self._callback, *self._args)\n    File \"/home/pib73/anaconda3/envs/with_TF_2_10/lib/python3.10/site-packages/ipykernel/kernelbase.py\", line 510, in dispatch_queue\n      await self.process_one()\n    File \"/home/pib73/anaconda3/envs/with_TF_2_10/lib/python3.10/site-packages/ipykernel/kernelbase.py\", line 499, in process_one\n      await dispatch(*args)\n    File \"/home/pib73/anaconda3/envs/with_TF_2_10/lib/python3.10/site-packages/ipykernel/kernelbase.py\", line 406, in dispatch_shell\n      await result\n    File \"/home/pib73/anaconda3/envs/with_TF_2_10/lib/python3.10/site-packages/ipykernel/kernelbase.py\", line 730, in execute_request\n      reply_content = await reply_content\n    File \"/home/pib73/anaconda3/envs/with_TF_2_10/lib/python3.10/site-packages/ipykernel/ipkernel.py\", line 383, in do_execute\n      res = shell.run_cell(\n    File \"/home/pib73/anaconda3/envs/with_TF_2_10/lib/python3.10/site-packages/ipykernel/zmqshell.py\", line 528, in run_cell\n      return super().run_cell(*args, **kwargs)\n    File \"/home/pib73/anaconda3/envs/with_TF_2_10/lib/python3.10/site-packages/IPython/core/interactiveshell.py\", line 2940, in run_cell\n      result = self._run_cell(\n    File \"/home/pib73/anaconda3/envs/with_TF_2_10/lib/python3.10/site-packages/IPython/core/interactiveshell.py\", line 2995, in _run_cell\n      return runner(coro)\n    File \"/home/pib73/anaconda3/envs/with_TF_2_10/lib/python3.10/site-packages/IPython/core/async_helpers.py\", line 129, in _pseudo_sync_runner\n      coro.send(None)\n    File \"/home/pib73/anaconda3/envs/with_TF_2_10/lib/python3.10/site-packages/IPython/core/interactiveshell.py\", line 3194, in run_cell_async\n      has_raised = await self.run_ast_nodes(code_ast.body, cell_name,\n    File \"/home/pib73/anaconda3/envs/with_TF_2_10/lib/python3.10/site-packages/IPython/core/interactiveshell.py\", line 3373, in run_ast_nodes\n      if await self.run_code(code, result, async_=asy):\n    File \"/home/pib73/anaconda3/envs/with_TF_2_10/lib/python3.10/site-packages/IPython/core/interactiveshell.py\", line 3433, in run_code\n      exec(code_obj, self.user_global_ns, self.user_ns)\n    File \"/tmp/ipykernel_31911/4059793443.py\", line 19, in <module>\n      historical = model.fit(training_dataset,\n    File \"/home/pib73/anaconda3/envs/with_TF_2_10/lib/python3.10/site-packages/keras/utils/traceback_utils.py\", line 65, in error_handler\n      return fn(*args, **kwargs)\n    File \"/home/pib73/anaconda3/envs/with_TF_2_10/lib/python3.10/site-packages/keras/engine/training.py\", line 1564, in fit\n      tmp_logs = self.train_function(iterator)\n    File \"/home/pib73/anaconda3/envs/with_TF_2_10/lib/python3.10/site-packages/keras/engine/training.py\", line 1160, in train_function\n      return step_function(self, iterator)\n    File \"/home/pib73/anaconda3/envs/with_TF_2_10/lib/python3.10/site-packages/keras/engine/training.py\", line 1146, in step_function\n      outputs = model.distribute_strategy.run(run_step, args=(data,))\n    File \"/home/pib73/anaconda3/envs/with_TF_2_10/lib/python3.10/site-packages/keras/engine/training.py\", line 1135, in run_step\n      outputs = model.train_step(data)\n    File \"/home/pib73/anaconda3/envs/with_TF_2_10/lib/python3.10/site-packages/keras/engine/training.py\", line 993, in train_step\n      y_pred = self(x, training=True)\n    File \"/home/pib73/anaconda3/envs/with_TF_2_10/lib/python3.10/site-packages/keras/utils/traceback_utils.py\", line 65, in error_handler\n      return fn(*args, **kwargs)\n    File \"/home/pib73/anaconda3/envs/with_TF_2_10/lib/python3.10/site-packages/keras/engine/training.py\", line 557, in __call__\n      return super().__call__(*args, **kwargs)\n    File \"/home/pib73/anaconda3/envs/with_TF_2_10/lib/python3.10/site-packages/keras/utils/traceback_utils.py\", line 65, in error_handler\n      return fn(*args, **kwargs)\n    File \"/home/pib73/anaconda3/envs/with_TF_2_10/lib/python3.10/site-packages/keras/engine/base_layer.py\", line 1097, in __call__\n      outputs = call_fn(inputs, *args, **kwargs)\n    File \"/home/pib73/anaconda3/envs/with_TF_2_10/lib/python3.10/site-packages/keras/utils/traceback_utils.py\", line 96, in error_handler\n      return fn(*args, **kwargs)\n    File \"/home/pib73/anaconda3/envs/with_TF_2_10/lib/python3.10/site-packages/keras/engine/sequential.py\", line 410, in call\n      return super().call(inputs, training=training, mask=mask)\n    File \"/home/pib73/anaconda3/envs/with_TF_2_10/lib/python3.10/site-packages/keras/engine/functional.py\", line 510, in call\n      return self._run_internal_graph(inputs, training=training, mask=mask)\n    File \"/home/pib73/anaconda3/envs/with_TF_2_10/lib/python3.10/site-packages/keras/engine/functional.py\", line 667, in _run_internal_graph\n      outputs = node.layer(*args, **kwargs)\n    File \"/home/pib73/anaconda3/envs/with_TF_2_10/lib/python3.10/site-packages/keras/utils/traceback_utils.py\", line 65, in error_handler\n      return fn(*args, **kwargs)\n    File \"/home/pib73/anaconda3/envs/with_TF_2_10/lib/python3.10/site-packages/keras/engine/training.py\", line 557, in __call__\n      return super().__call__(*args, **kwargs)\n    File \"/home/pib73/anaconda3/envs/with_TF_2_10/lib/python3.10/site-packages/keras/utils/traceback_utils.py\", line 65, in error_handler\n      return fn(*args, **kwargs)\n    File \"/home/pib73/anaconda3/envs/with_TF_2_10/lib/python3.10/site-packages/keras/engine/base_layer.py\", line 1097, in __call__\n      outputs = call_fn(inputs, *args, **kwargs)\n    File \"/home/pib73/anaconda3/envs/with_TF_2_10/lib/python3.10/site-packages/keras/utils/traceback_utils.py\", line 96, in error_handler\n      return fn(*args, **kwargs)\n    File \"/home/pib73/anaconda3/envs/with_TF_2_10/lib/python3.10/site-packages/keras/engine/functional.py\", line 510, in call\n      return self._run_internal_graph(inputs, training=training, mask=mask)\n    File \"/home/pib73/anaconda3/envs/with_TF_2_10/lib/python3.10/site-packages/keras/engine/functional.py\", line 667, in _run_internal_graph\n      outputs = node.layer(*args, **kwargs)\n    File \"/home/pib73/anaconda3/envs/with_TF_2_10/lib/python3.10/site-packages/keras/utils/traceback_utils.py\", line 65, in error_handler\n      return fn(*args, **kwargs)\n    File \"/home/pib73/anaconda3/envs/with_TF_2_10/lib/python3.10/site-packages/keras/engine/base_layer.py\", line 1097, in __call__\n      outputs = call_fn(inputs, *args, **kwargs)\n    File \"/home/pib73/anaconda3/envs/with_TF_2_10/lib/python3.10/site-packages/keras/utils/traceback_utils.py\", line 96, in error_handler\n      return fn(*args, **kwargs)\n    File \"/home/pib73/anaconda3/envs/with_TF_2_10/lib/python3.10/site-packages/keras/layers/convolutional/base_conv.py\", line 314, in call\n      return self.activation(outputs)\n    File \"/home/pib73/anaconda3/envs/with_TF_2_10/lib/python3.10/site-packages/keras/activations.py\", line 317, in relu\n      return backend.relu(\n    File \"/home/pib73/anaconda3/envs/with_TF_2_10/lib/python3.10/site-packages/keras/backend.py\", line 5366, in relu\n      x = tf.nn.relu(x)\nNode: 'sequential_1/vgg16/block1_conv1/Relu'\nNo algorithm worked!  Error messages:\n  Profiling failure on CUDNN engine eng11{}: UNKNOWN: CUDNN_STATUS_ALLOC_FAILED\nin tensorflow/stream_executor/cuda/cuda_dnn.cc(4369): 'status'\n  Profiling failure on CUDNN engine eng0{}: UNKNOWN: CUDNN_STATUS_ALLOC_FAILED\nin tensorflow/stream_executor/cuda/cuda_dnn.cc(4369): 'status'\n\t [[{{node sequential_1/vgg16/block1_conv1/Relu}}]] [Op:__inference_train_function_2827]",
     "output_type": "error",
     "traceback": [
      "\u001b[0;31m---------------------------------------------------------------------------\u001b[0m",
      "\u001b[0;31mNotFoundError\u001b[0m                             Traceback (most recent call last)",
      "Cell \u001b[0;32mIn [19], line 19\u001b[0m\n\u001b[1;32m     11\u001b[0m     f1_score \u001b[38;5;241m=\u001b[39m tfa\u001b[38;5;241m.\u001b[39mmetrics\u001b[38;5;241m.\u001b[39mF1Score(\u001b[38;5;241m104\u001b[39m, \u001b[38;5;124m'\u001b[39m\u001b[38;5;124mmacro\u001b[39m\u001b[38;5;124m'\u001b[39m)\n\u001b[1;32m     13\u001b[0m model\u001b[38;5;241m.\u001b[39mcompile(\n\u001b[1;32m     14\u001b[0m     optimizer\u001b[38;5;241m=\u001b[39m\u001b[38;5;124m'\u001b[39m\u001b[38;5;124madam\u001b[39m\u001b[38;5;124m'\u001b[39m,\n\u001b[1;32m     15\u001b[0m     loss \u001b[38;5;241m=\u001b[39m \u001b[38;5;124m'\u001b[39m\u001b[38;5;124msparse_categorical_crossentropy\u001b[39m\u001b[38;5;124m'\u001b[39m,\n\u001b[1;32m     16\u001b[0m     metrics\u001b[38;5;241m=\u001b[39m[\u001b[38;5;124m'\u001b[39m\u001b[38;5;124msparse_categorical_accuracy\u001b[39m\u001b[38;5;124m'\u001b[39m]\n\u001b[1;32m     17\u001b[0m )\n\u001b[0;32m---> 19\u001b[0m historical \u001b[38;5;241m=\u001b[39m \u001b[43mmodel\u001b[49m\u001b[38;5;241;43m.\u001b[39;49m\u001b[43mfit\u001b[49m\u001b[43m(\u001b[49m\u001b[43mtraining_dataset\u001b[49m\u001b[43m,\u001b[49m\u001b[43m \u001b[49m\n\u001b[1;32m     20\u001b[0m \u001b[43m          \u001b[49m\u001b[43msteps_per_epoch\u001b[49m\u001b[38;5;241;43m=\u001b[39;49m\u001b[43mSTEPS_PER_EPOCH\u001b[49m\u001b[43m,\u001b[49m\u001b[43m \u001b[49m\n\u001b[1;32m     21\u001b[0m \u001b[43m          \u001b[49m\u001b[43mepochs\u001b[49m\u001b[38;5;241;43m=\u001b[39;49m\u001b[43mEPOCHS\u001b[49m\u001b[43m,\u001b[49m\u001b[43m \u001b[49m\n\u001b[1;32m     22\u001b[0m \u001b[43m          \u001b[49m\u001b[43mvalidation_data\u001b[49m\u001b[38;5;241;43m=\u001b[39;49m\u001b[43mvalidation_dataset\u001b[49m\u001b[43m)\u001b[49m\n",
      "File \u001b[0;32m~/anaconda3/envs/with_TF_2_10/lib/python3.10/site-packages/keras/utils/traceback_utils.py:70\u001b[0m, in \u001b[0;36mfilter_traceback.<locals>.error_handler\u001b[0;34m(*args, **kwargs)\u001b[0m\n\u001b[1;32m     67\u001b[0m     filtered_tb \u001b[38;5;241m=\u001b[39m _process_traceback_frames(e\u001b[38;5;241m.\u001b[39m__traceback__)\n\u001b[1;32m     68\u001b[0m     \u001b[38;5;66;03m# To get the full stack trace, call:\u001b[39;00m\n\u001b[1;32m     69\u001b[0m     \u001b[38;5;66;03m# `tf.debugging.disable_traceback_filtering()`\u001b[39;00m\n\u001b[0;32m---> 70\u001b[0m     \u001b[38;5;28;01mraise\u001b[39;00m e\u001b[38;5;241m.\u001b[39mwith_traceback(filtered_tb) \u001b[38;5;28;01mfrom\u001b[39;00m \u001b[38;5;28mNone\u001b[39m\n\u001b[1;32m     71\u001b[0m \u001b[38;5;28;01mfinally\u001b[39;00m:\n\u001b[1;32m     72\u001b[0m     \u001b[38;5;28;01mdel\u001b[39;00m filtered_tb\n",
      "File \u001b[0;32m~/anaconda3/envs/with_TF_2_10/lib/python3.10/site-packages/tensorflow/python/eager/execute.py:54\u001b[0m, in \u001b[0;36mquick_execute\u001b[0;34m(op_name, num_outputs, inputs, attrs, ctx, name)\u001b[0m\n\u001b[1;32m     52\u001b[0m \u001b[38;5;28;01mtry\u001b[39;00m:\n\u001b[1;32m     53\u001b[0m   ctx\u001b[38;5;241m.\u001b[39mensure_initialized()\n\u001b[0;32m---> 54\u001b[0m   tensors \u001b[38;5;241m=\u001b[39m pywrap_tfe\u001b[38;5;241m.\u001b[39mTFE_Py_Execute(ctx\u001b[38;5;241m.\u001b[39m_handle, device_name, op_name,\n\u001b[1;32m     55\u001b[0m                                       inputs, attrs, num_outputs)\n\u001b[1;32m     56\u001b[0m \u001b[38;5;28;01mexcept\u001b[39;00m core\u001b[38;5;241m.\u001b[39m_NotOkStatusException \u001b[38;5;28;01mas\u001b[39;00m e:\n\u001b[1;32m     57\u001b[0m   \u001b[38;5;28;01mif\u001b[39;00m name \u001b[38;5;129;01mis\u001b[39;00m \u001b[38;5;129;01mnot\u001b[39;00m \u001b[38;5;28;01mNone\u001b[39;00m:\n",
      "\u001b[0;31mNotFoundError\u001b[0m: Graph execution error:\n\nDetected at node 'sequential_1/vgg16/block1_conv1/Relu' defined at (most recent call last):\n    File \"/home/pib73/anaconda3/envs/with_TF_2_10/lib/python3.10/runpy.py\", line 196, in _run_module_as_main\n      return _run_code(code, main_globals, None,\n    File \"/home/pib73/anaconda3/envs/with_TF_2_10/lib/python3.10/runpy.py\", line 86, in _run_code\n      exec(code, run_globals)\n    File \"/home/pib73/anaconda3/envs/with_TF_2_10/lib/python3.10/site-packages/ipykernel_launcher.py\", line 17, in <module>\n      app.launch_new_instance()\n    File \"/home/pib73/anaconda3/envs/with_TF_2_10/lib/python3.10/site-packages/traitlets/config/application.py\", line 982, in launch_instance\n      app.start()\n    File \"/home/pib73/anaconda3/envs/with_TF_2_10/lib/python3.10/site-packages/ipykernel/kernelapp.py\", line 712, in start\n      self.io_loop.start()\n    File \"/home/pib73/anaconda3/envs/with_TF_2_10/lib/python3.10/site-packages/tornado/platform/asyncio.py\", line 215, in start\n      self.asyncio_loop.run_forever()\n    File \"/home/pib73/anaconda3/envs/with_TF_2_10/lib/python3.10/asyncio/base_events.py\", line 600, in run_forever\n      self._run_once()\n    File \"/home/pib73/anaconda3/envs/with_TF_2_10/lib/python3.10/asyncio/base_events.py\", line 1896, in _run_once\n      handle._run()\n    File \"/home/pib73/anaconda3/envs/with_TF_2_10/lib/python3.10/asyncio/events.py\", line 80, in _run\n      self._context.run(self._callback, *self._args)\n    File \"/home/pib73/anaconda3/envs/with_TF_2_10/lib/python3.10/site-packages/ipykernel/kernelbase.py\", line 510, in dispatch_queue\n      await self.process_one()\n    File \"/home/pib73/anaconda3/envs/with_TF_2_10/lib/python3.10/site-packages/ipykernel/kernelbase.py\", line 499, in process_one\n      await dispatch(*args)\n    File \"/home/pib73/anaconda3/envs/with_TF_2_10/lib/python3.10/site-packages/ipykernel/kernelbase.py\", line 406, in dispatch_shell\n      await result\n    File \"/home/pib73/anaconda3/envs/with_TF_2_10/lib/python3.10/site-packages/ipykernel/kernelbase.py\", line 730, in execute_request\n      reply_content = await reply_content\n    File \"/home/pib73/anaconda3/envs/with_TF_2_10/lib/python3.10/site-packages/ipykernel/ipkernel.py\", line 383, in do_execute\n      res = shell.run_cell(\n    File \"/home/pib73/anaconda3/envs/with_TF_2_10/lib/python3.10/site-packages/ipykernel/zmqshell.py\", line 528, in run_cell\n      return super().run_cell(*args, **kwargs)\n    File \"/home/pib73/anaconda3/envs/with_TF_2_10/lib/python3.10/site-packages/IPython/core/interactiveshell.py\", line 2940, in run_cell\n      result = self._run_cell(\n    File \"/home/pib73/anaconda3/envs/with_TF_2_10/lib/python3.10/site-packages/IPython/core/interactiveshell.py\", line 2995, in _run_cell\n      return runner(coro)\n    File \"/home/pib73/anaconda3/envs/with_TF_2_10/lib/python3.10/site-packages/IPython/core/async_helpers.py\", line 129, in _pseudo_sync_runner\n      coro.send(None)\n    File \"/home/pib73/anaconda3/envs/with_TF_2_10/lib/python3.10/site-packages/IPython/core/interactiveshell.py\", line 3194, in run_cell_async\n      has_raised = await self.run_ast_nodes(code_ast.body, cell_name,\n    File \"/home/pib73/anaconda3/envs/with_TF_2_10/lib/python3.10/site-packages/IPython/core/interactiveshell.py\", line 3373, in run_ast_nodes\n      if await self.run_code(code, result, async_=asy):\n    File \"/home/pib73/anaconda3/envs/with_TF_2_10/lib/python3.10/site-packages/IPython/core/interactiveshell.py\", line 3433, in run_code\n      exec(code_obj, self.user_global_ns, self.user_ns)\n    File \"/tmp/ipykernel_31911/4059793443.py\", line 19, in <module>\n      historical = model.fit(training_dataset,\n    File \"/home/pib73/anaconda3/envs/with_TF_2_10/lib/python3.10/site-packages/keras/utils/traceback_utils.py\", line 65, in error_handler\n      return fn(*args, **kwargs)\n    File \"/home/pib73/anaconda3/envs/with_TF_2_10/lib/python3.10/site-packages/keras/engine/training.py\", line 1564, in fit\n      tmp_logs = self.train_function(iterator)\n    File \"/home/pib73/anaconda3/envs/with_TF_2_10/lib/python3.10/site-packages/keras/engine/training.py\", line 1160, in train_function\n      return step_function(self, iterator)\n    File \"/home/pib73/anaconda3/envs/with_TF_2_10/lib/python3.10/site-packages/keras/engine/training.py\", line 1146, in step_function\n      outputs = model.distribute_strategy.run(run_step, args=(data,))\n    File \"/home/pib73/anaconda3/envs/with_TF_2_10/lib/python3.10/site-packages/keras/engine/training.py\", line 1135, in run_step\n      outputs = model.train_step(data)\n    File \"/home/pib73/anaconda3/envs/with_TF_2_10/lib/python3.10/site-packages/keras/engine/training.py\", line 993, in train_step\n      y_pred = self(x, training=True)\n    File \"/home/pib73/anaconda3/envs/with_TF_2_10/lib/python3.10/site-packages/keras/utils/traceback_utils.py\", line 65, in error_handler\n      return fn(*args, **kwargs)\n    File \"/home/pib73/anaconda3/envs/with_TF_2_10/lib/python3.10/site-packages/keras/engine/training.py\", line 557, in __call__\n      return super().__call__(*args, **kwargs)\n    File \"/home/pib73/anaconda3/envs/with_TF_2_10/lib/python3.10/site-packages/keras/utils/traceback_utils.py\", line 65, in error_handler\n      return fn(*args, **kwargs)\n    File \"/home/pib73/anaconda3/envs/with_TF_2_10/lib/python3.10/site-packages/keras/engine/base_layer.py\", line 1097, in __call__\n      outputs = call_fn(inputs, *args, **kwargs)\n    File \"/home/pib73/anaconda3/envs/with_TF_2_10/lib/python3.10/site-packages/keras/utils/traceback_utils.py\", line 96, in error_handler\n      return fn(*args, **kwargs)\n    File \"/home/pib73/anaconda3/envs/with_TF_2_10/lib/python3.10/site-packages/keras/engine/sequential.py\", line 410, in call\n      return super().call(inputs, training=training, mask=mask)\n    File \"/home/pib73/anaconda3/envs/with_TF_2_10/lib/python3.10/site-packages/keras/engine/functional.py\", line 510, in call\n      return self._run_internal_graph(inputs, training=training, mask=mask)\n    File \"/home/pib73/anaconda3/envs/with_TF_2_10/lib/python3.10/site-packages/keras/engine/functional.py\", line 667, in _run_internal_graph\n      outputs = node.layer(*args, **kwargs)\n    File \"/home/pib73/anaconda3/envs/with_TF_2_10/lib/python3.10/site-packages/keras/utils/traceback_utils.py\", line 65, in error_handler\n      return fn(*args, **kwargs)\n    File \"/home/pib73/anaconda3/envs/with_TF_2_10/lib/python3.10/site-packages/keras/engine/training.py\", line 557, in __call__\n      return super().__call__(*args, **kwargs)\n    File \"/home/pib73/anaconda3/envs/with_TF_2_10/lib/python3.10/site-packages/keras/utils/traceback_utils.py\", line 65, in error_handler\n      return fn(*args, **kwargs)\n    File \"/home/pib73/anaconda3/envs/with_TF_2_10/lib/python3.10/site-packages/keras/engine/base_layer.py\", line 1097, in __call__\n      outputs = call_fn(inputs, *args, **kwargs)\n    File \"/home/pib73/anaconda3/envs/with_TF_2_10/lib/python3.10/site-packages/keras/utils/traceback_utils.py\", line 96, in error_handler\n      return fn(*args, **kwargs)\n    File \"/home/pib73/anaconda3/envs/with_TF_2_10/lib/python3.10/site-packages/keras/engine/functional.py\", line 510, in call\n      return self._run_internal_graph(inputs, training=training, mask=mask)\n    File \"/home/pib73/anaconda3/envs/with_TF_2_10/lib/python3.10/site-packages/keras/engine/functional.py\", line 667, in _run_internal_graph\n      outputs = node.layer(*args, **kwargs)\n    File \"/home/pib73/anaconda3/envs/with_TF_2_10/lib/python3.10/site-packages/keras/utils/traceback_utils.py\", line 65, in error_handler\n      return fn(*args, **kwargs)\n    File \"/home/pib73/anaconda3/envs/with_TF_2_10/lib/python3.10/site-packages/keras/engine/base_layer.py\", line 1097, in __call__\n      outputs = call_fn(inputs, *args, **kwargs)\n    File \"/home/pib73/anaconda3/envs/with_TF_2_10/lib/python3.10/site-packages/keras/utils/traceback_utils.py\", line 96, in error_handler\n      return fn(*args, **kwargs)\n    File \"/home/pib73/anaconda3/envs/with_TF_2_10/lib/python3.10/site-packages/keras/layers/convolutional/base_conv.py\", line 314, in call\n      return self.activation(outputs)\n    File \"/home/pib73/anaconda3/envs/with_TF_2_10/lib/python3.10/site-packages/keras/activations.py\", line 317, in relu\n      return backend.relu(\n    File \"/home/pib73/anaconda3/envs/with_TF_2_10/lib/python3.10/site-packages/keras/backend.py\", line 5366, in relu\n      x = tf.nn.relu(x)\nNode: 'sequential_1/vgg16/block1_conv1/Relu'\nNo algorithm worked!  Error messages:\n  Profiling failure on CUDNN engine eng11{}: UNKNOWN: CUDNN_STATUS_ALLOC_FAILED\nin tensorflow/stream_executor/cuda/cuda_dnn.cc(4369): 'status'\n  Profiling failure on CUDNN engine eng0{}: UNKNOWN: CUDNN_STATUS_ALLOC_FAILED\nin tensorflow/stream_executor/cuda/cuda_dnn.cc(4369): 'status'\n\t [[{{node sequential_1/vgg16/block1_conv1/Relu}}]] [Op:__inference_train_function_2827]"
     ]
    }
   ],
   "source": [
    "with strategy.scope():    \n",
    "    pretrained_model = tf.keras.applications.VGG16(weights='imagenet', include_top=False ,input_shape=[*IMAGE_SIZE, 3])\n",
    "    pretrained_model.trainable = False # tramsfer learning\n",
    "    \n",
    "    model = tf.keras.Sequential([\n",
    "        pretrained_model,\n",
    "        tf.keras.layers.GlobalAveragePooling2D(),\n",
    "        tf.keras.layers.Dense(104, activation='softmax')\n",
    "    ])\n",
    "    \n",
    "    f1_score = tfa.metrics.F1Score(104, 'macro')\n",
    "        \n",
    "model.compile(\n",
    "    optimizer='adam',\n",
    "    loss = 'sparse_categorical_crossentropy',\n",
    "    metrics=['sparse_categorical_accuracy']\n",
    ")\n",
    "\n",
    "historical = model.fit(training_dataset, \n",
    "          steps_per_epoch=STEPS_PER_EPOCH, \n",
    "          epochs=EPOCHS, \n",
    "          validation_data=validation_dataset)"
   ]
  },
  {
   "cell_type": "markdown",
   "metadata": {},
   "source": [
    "# Compute your predictions on the test set!\n",
    "\n",
    "This will create a file that can be submitted to the competition."
   ]
  },
  {
   "cell_type": "code",
   "execution_count": 8,
   "metadata": {
    "execution": {
     "iopub.execute_input": "2022-11-07T05:36:28.023449Z",
     "iopub.status.busy": "2022-11-07T05:36:28.023153Z",
     "iopub.status.idle": "2022-11-07T05:36:57.235236Z",
     "shell.execute_reply": "2022-11-07T05:36:57.233971Z",
     "shell.execute_reply.started": "2022-11-07T05:36:28.023418Z"
    }
   },
   "outputs": [
    {
     "name": "stderr",
     "output_type": "stream",
     "text": [
      "2022-11-07 05:36:28.026902: I tensorflow/core/platform/cloud/google_auth_provider.cc:180] Attempting an empty bearer token since no token was retrieved from files, and GCE metadata check was skipped.\n"
     ]
    },
    {
     "name": "stdout",
     "output_type": "stream",
     "text": [
      "Computing predictions...\n"
     ]
    },
    {
     "name": "stderr",
     "output_type": "stream",
     "text": [
      "2022-11-07 05:36:51.408493: W ./tensorflow/core/distributed_runtime/eager/destroy_tensor_handle_node.h:57] Ignoring an error encountered when deleting remote tensors handles: Invalid argument: Unable to find the relevant tensor remote_handle: Op ID: 7955, Output num: 0\n",
      "Additional GRPC error information from remote target /job:worker/replica:0/task:0:\n",
      ":{\"created\":\"@1667799411.408225175\",\"description\":\"Error received from peer ipv4:10.0.0.2:8470\",\"file\":\"external/com_github_grpc_grpc/src/core/lib/surface/call.cc\",\"file_line\":1056,\"grpc_message\":\"Unable to find the relevant tensor remote_handle: Op ID: 7955, Output num: 0\",\"grpc_status\":3}\n"
     ]
    },
    {
     "name": "stdout",
     "output_type": "stream",
     "text": [
      "[ 67  45 103 ...  43  53  73]\n",
      "Generating submission.csv file...\n"
     ]
    }
   ],
   "source": [
    "test_ds = get_test_dataset(ordered=True) # since we are splitting the dataset and iterating separately on images and ids, order matters.\n",
    "\n",
    "print('Computing predictions...')\n",
    "test_images_ds = test_ds.map(lambda image, idnum: image)\n",
    "probabilities = model.predict(test_images_ds)\n",
    "predictions = np.argmax(probabilities, axis=-1)\n",
    "print(predictions)\n",
    "\n",
    "print('Generating submission.csv file...')\n",
    "test_ids_ds = test_ds.map(lambda image, idnum: idnum).unbatch()\n",
    "test_ids = next(iter(test_ids_ds.batch(NUM_TEST_IMAGES))).numpy().astype('U') # all in one batch\n",
    "np.savetxt('submission.csv', np.rec.fromarrays([test_ids, predictions]), fmt=['%s', '%d'], delimiter=',', header='id,label', comments='')"
   ]
  },
  {
   "cell_type": "code",
   "execution_count": null,
   "metadata": {},
   "outputs": [],
   "source": []
  }
 ],
 "metadata": {
  "kernelspec": {
   "display_name": "with_TF_2_10",
   "language": "python",
   "name": "with_tf_2_10"
  },
  "language_info": {
   "codemirror_mode": {
    "name": "ipython",
    "version": 3
   },
   "file_extension": ".py",
   "mimetype": "text/x-python",
   "name": "python",
   "nbconvert_exporter": "python",
   "pygments_lexer": "ipython3",
   "version": "3.10.6"
  }
 },
 "nbformat": 4,
 "nbformat_minor": 4
}
